Workbook
Name WACC_TGR: 'DCF Model'!$D$60

Sheet Summary Dashboard
C4: Rio Tinto - INVESTMENT SUMMARY DASHBOARD Valuation Date: June 2026 Base Case Assumptions: WACC 7.5% | TGR 2.5%
C6: All outputs link dynamically to DCF Model sheet. Change WACC or TGR in DCF Model and this dashboard updates automatically.
C8: VALUATION SUMMARY
C9: Enterprise Value | D9: Equity Value | E9: Intrinsic Value (USD) | F9: Intrinsic Value (AUD) | G9: Market Price | H9: Upside / (Downside) | I9: WACC | J9: Recommendation
C10: ='DCF Model'!D47 -> 217757.32 | D10: ='DCF Model'!D49 -> 203395.32 | E10: ='DCF Model'!D51 -> 125.32059 | F10: ='DCF Model'!D53 -> 194.29549 | G10: ='DCF Model'!D54 -> 179.79 | H10: ='DCF Model'!D55 -> 0.080680185 | I10: ='DCF Model'!D8 -> 0.075 | J10: ='DCF Model'!D56 -> BUY
C11: USD $m | D11: USD $m | E11: per share | F11: per share | G11: ASX: RIO Investing.com (22 May 2026) | H11: vs market | I11: discount rate | J11: BUY/HOLD/SELL
C13: 5-YEAR FINANCIAL SNAPSHOT (USD $m)
C14: Particulars | D14: FY2021 | E14: FY2022 | F14: FY2023 | G14: FY2024 | H14: FY2025 | I14: Trend
C15: Revenue | D15: 63495 | E15: 55554 | F15: 54041 | G15: 53658 | H15: 57638 | I15: ↑
C16: Underlying EBITDA | D16: 37720 | E16: 26272 | F16: 23892 | G16: 23314 | H16: 25363 | I16: ↑
C17: Net Earnings | D17: 21094 | E17: 12420 | F17: 10058 | G17: 11552 | H17: 9966 | I17: ↓
C18: Free Cash Flow | D18: 17664 | E18: 9010 | F18: 7657 | G18: 5553 | H18: 4025 | I18: ↓
C19: Net Debt/(Cash) | D19: -1576 | E19: 4189 | F19: 4231 | G19: 5491 | H19: 14362 | I19: ↑
C21: SCENARIO COMPARISON (AUD per share)
C22: Scenario | D22: Intrinsic Value | E22: vs Market | F22: Recommendation | G22: Key Assumption
C23: Bear Case | D23: 73.24 | E23: -0.5926 | F23: SELL | G23: WACC 8.68%, TGR 1.5%, EBITDA 40%
C24: Base Case | D24: 195.96 | E24: 0.0899 | F24: BUY | G24: WACC 7.50%, TGR 2.5%, EBITDA 44.5%
C25: Bull Case | D25: 370.98 | E25: 1.0634 | F25: BUY | G25: WACC 6.50%, TGR 3.0%, EBITDA 47%

Sheet Historical Financials
C3: RIO TINTO GROUP — HISTORICAL FINANCIALS (USD $m)
C4: Source: Rio Tinto Full Year Results FY2021–FY2025
C6: INCOME STATEMENT
C7: Particulars (USD $m) | D7: FY2021 | E7: FY2022 | F7: FY2023 | G7: FY2024 | H7: FY2025 | I7: Source / Notes
C8: Revenue | D8: 63495 | E8: 55554 | F8: 54041 | G8: 53658 | H8: 57638 | I8: Rio Tinto 2025 Full Year Results, SEC EDGAR 6-K 19 Feb 2026
C9: Underlying EBITDA | D9: 37720 | E9: 26272 | F9: 23892 | G9: 23314 | H9: 25363 | I9: Rio Tinto Full Year Results FY2021-FY2025
C10: EBITDA Margin % | D10: =D9/D8 -> 0.59406252 | E10: =E9/E8 -> 0.47290924 | F10: =F9/F8 -> 0.44210877 | G10: =G9/G8 -> 0.43449253 | H10: =H9/H8 -> 0.44003956 | I10: underlying ebitda / revenue
C11: Underlying EBIT | D11: 19802 | E11: 14167 | F11: 12001 | G11: 10896 | H11: 11876 | I11: Rio Tinto Full Year Results FY2021-FY2025
C12: EBIT Margin % | D12: =D11/D8 -> 0.31186708 | E12: =E11/E8 -> 0.25501314 | F12: =F11/F8 -> 0.22207213 | G12: =G11/G8 -> 0.20306385 | H12: =H11/H8 -> 0.20604462 | I12: underlying ebit / revenue
C13: Net Earnings (attrib) | D13: 21094 | E13: 12420 | F13: 10058 | G13: 11552 | H13: 9966 | I13: Rio Tinto Full Year Results. FY2022: $12,392m official; $12,420m as reported in some sources
C14: Net Margin % | D14: =D13/D8 -> 0.33221514 | E14: =E13/E8 -> 0.22356626 | F14: =F13/F8 -> 0.18611795 | G14: =G13/G8 -> 0.21528943 | H14: =H13/H8 -> 0.17290676 | I14: net earnings / revenue
C15: Underlying Earnings | D15: 21380 | E15: 13275 | F15: 11763 | G15: 10872 | H15: 10867 | I15: Rio Tinto Full Year Results FY2021-FY2025
C16: Net EPS (US cents) | D16: 1299 | E16: 766.9 | F16: 622.8 | G16: 711.7 | H16: 613.7 | I16: Net EPS (not underlying EPS). FY2021 underlying EPS = 1,321c
C17: DPS (US cents) | D17: 1040 | E17: 492 | F17: 435 | G17: 402 | H17: 402 | I17: Rio Tinto Full Year Results FY2021-FY2025
C20: CASH FLOW STATEMENT
C21: Particulars (USD $m) | D21: FY2021 | E21: FY2022 | F21: FY2023 | G21: FY2024 | H21: FY2025
C22: Operating Cash Flow (OCF) | D22: 25345 | E22: 16134 | F22: 15160 | G22: 15599 | H22: 16832
C23: Capital Expenditure (CapEx) | D23: 7384 | E23: 6750 | F23: 7086 | G23: 9621 | H23: 12335
C24: Free Cash Flow (FCF) | D24: 17664 | E24: 9010 | F24: 7657 | G24: 5553 | H24: 4025
C25: Dividends Paid | D25: 16800 | E25: 13046 | F25: 7656 | G25: 6500 | H25: 6500
C26: FCF Conversion % | D26: =D24/D22 -> 0.6969422 | E26: =E24/E22 -> 0.558448 | F26: =F24/F22 -> 0.50507916 | G26: =G24/G22 -> 0.35598436 | H26: =H24/H22 -> 0.23912785
C29: BALANCE SHEET
C30: Particulars (USD $m) | D30: FY2021 | E30: FY2022 | F30: FY2023 | G30: FY2024 | H30: FY2025
C31: Total Assets | D31: 98063 | E31: 93099 | F31: 89993 | G31: 99095 | H31: 117668
C32: Total Equity (incl. NCI) | D32: 46578 | E32: 47012 | F32: 46913 | G32: 54020 | H32: 67024
C33: Total Debt (borrowings+leases) | D33: 16434 | E33: 14513 | F33: 13741 | G33: 16889 | H33: 23517
C34: Net Debt / (Net Cash) | D34: -1576 | E34: 4189 | F34: 4231 | G34: 5491 | H34: 14362
C35: Net Debt / EBITDA | D35: =D34/D9 -> -0.041781548 | E35: =E34/E9 -> 0.15944732 | F35: =F34/F9 -> 0.17708857 | G35: =G34/G9 -> 0.23552372 | H35: =H34/H9 -> 0.56625793
C36: Equity Ratio % | D36: =D32/D31 -> 0.47498037 | E36: =E32/E31 -> 0.50496783 | F36: =F32/F31 -> 0.5212961 | G36: =G32/G31 -> 0.54513346 | H36: =H32/H31 -> 0.56960261
C39: KEY RATIOS
C40: Particulars (USD $m) | D40: FY2021 | E40: FY2022 | F40: FY2023 | G40: FY2024 | H40: FY2025
C41: ROCE % | D41: 0.44 | E41: 0.25 | F41: 0.2 | G41: 0.18 | H41: 0.16
C42: Revenue Growth | E42: =(E8-D8)/D8 -> -0.12506497 | F42: =(F8-E8)/E8 -> -0.027234763 | G42: =(G8-F8)/F8 -> -0.0070872116 | H42: =(H8-G8)/G8 -> 0.074173469
C43: EBITDA Growth | E43: =(E9-D9)/D9 -> -0.30349947 | F43: =(F9-E9)/E9 -> -0.090590743 | G43: =(G9-F9)/F9 -> -0.024192198 | H43: =(H9-G9)/G9 -> 0.087887106
C44: FCF Growth | E44: =(E24-D24)/D24 -> -0.48992301 | F44: =(F24-E24)/E24 -> -0.15016648 | G44: =(G24-F24)/F24 -> -0.27478125 | H44: =(H24-G24)/G24 -> -0.27516658
C46: Rio Tinto Revenue and EBITDA Trend
C47: Year | D47: Revenue | E47: EBITDA
C48: FY2021 | D48: 63495 | E48: 37720
C49: FY2022 | D49: 55554 | E49: 26272
C50: FY2023 | D50: 54041 | E50: 23892
...

Sheet WACC Derivation
C3: RIO TINTO GROUP — WACC DERIVATION
C5: A. COST OF EQUITY — CAPM: Ke = Rf + β × (Rm − Rf)
C6: Component | D6: Value | E6: Basis / Source
C7: Risk-free rate (Rf) | D7: 0.0492 | E7: Australia 10-yr Commonwealth Govt Bond yield, June 2026 (tradingeconomics.com)
C8: Equity Risk Premium (ERP) | D8: 0.06 | E8: Long-run Australian ERP; Damodaran (2026) country risk estimate
C9: Beta (β) | D9: 0.95 | E9: Mining sector beta; commodity cycle exposure offset by diversification
C10: Cost of Equity (Ke = Rf + β × ERP) | D10: =D7+D9*D8 -> 0.1062 | E10: CAPM formula
C12: B. COST OF DEBT: Kd (after-tax) = Pre-tax Kd × (1 − Tax Rate)
C13: Component | D13: Value | E13: Basis / Source
C14: Pre-tax cost of debt | D14: 0.045 | E14: Single-A rated; based on reported borrowing costs & credit spreads
C15: Corporate tax rate | D15: 0.3 | E15: Australian corporate tax rate
C16: After-tax cost of debt (Kd) | D16: =D14*(1-D15) -> 0.0315
C18: C. CAPITAL STRUCTURE WEIGHTS (FY2025 Balance Sheet)
C19: Component | D19: Value (USD $m) | E19: Basis / Source
C20: Total equity (incl. NCI) | D20: 67024 | E20: FY2025 balance sheet (Historical Financials sheet)
C21: Total debt (borrowings + leases) | D21: 23517 | E21: FY2025: current + non-current borrowings and lease liabilities
C22: Total capital (E + D) | D22: =D20+D21 -> 90541
C23: Weight of equity (E/V) | D23: =D20/D22 -> 0.74026132
C24: Weight of debt (D/V) | D24: =D21/D22 -> 0.25973868
C26: D. WACC CALCULATION: WACC = (E/V × Ke) + (D/V × Kd)
C27: Component | D27: Value | E27: Basis / Source
C28: WACC (formula-derived) | D28: =D23*D10+D24*D16 -> 0.08679752 | E28: Full CAPM-derived WACC using balance sheet weights
C29: WACC — BASE CASE (used in DCF) | D29: 0.075 | E29: Adjusted downward vs formula rate: reflects first-quartile cost position & operating resilience
C30: Conservatism buffer | D30: =D28-D29 -> 0.01179752 | E30: Difference between formula WACC and base-case WACC

Sheet DCF Model
C4: RIO TINTO GROUP — DCF VALUATION MODEL (USD $m)
C6: KEY ASSUMPTIONS
C7: Particulars | D7: Value | E7: Basis / Source
C8: WACC (base case) | D8: 0.075
C9: Terminal Growth Rate (TGR) | D9: 0.025
C10: EBITDA Margin | D10: 0.445 | E10: 5-yr avg 47.7%; set conservatively at trough level
C11: EBIT Margin | D11: 0.26 | E11: Consistent with FY2023-FY2025 reported margins
C12: Effective Tax Rate | D12: 0.28 | E12: Blended effective rate based on 5-year average
C13: D&A as % of Revenue | D13: 0.1845 | E13: FY2025: (EBITDA-EBIT)/Revenue = 18.45%
C14: CapEx Base (FY2025 $m) | D14: 12335 | E14: Source: Rio Tinto FY2025 Full Year Results
C15: CapEx Growth Rate p.a. | D15: 0.015 | E15: Moderate tapering from FY2025 record spend
C16: Revenue Yr1 Growth | D16: 0.04 | E16: Based on FY2025 rebound trajectory
C17: WC Change p.a. ($m) | D17: 300 | E17: Conservative working capital build
C19: REVENUE FORECAST
C20: Particulars | D20: FY2026 | E20: FY2027 | F20: FY2028 | G20: FY2029 | H20: FY2030 | I20: 5-Yr Avg / Total | J20: Notes
C21: Revenue Growth % | D21: =D16 -> 0.04 | E21: =D21*0.99 -> 0.0396 | F21: =E21*0.975 -> 0.03861 | G21: =F21*0.96 -> 0.0370656 | H21: =G21*0.96 -> 0.035582976 | I21: =AVERAGE(D21:H21) -> 0.038171715 | J21: Yr1 from assumption; tapering toward long-run CAGR
C22: Revenue ($m) | D22: ='Historical Financials'!$H$8*(1+D21) -> 59943.52 | E22: =D22*(1+E21) -> 62317.283 | F22: =E22*(1+F21) -> 64723.354 | G22: =F22*(1+G21) -> 67122.364 | H22: =G22*(1+H21) -> 69510.777 | I22: =AVERAGE(D22:H22) -> 64723.46 | J22: Links to FY2025 actual revenue ($57,638m)
C24: FREE CASH FLOW TO FIRM (FCFF) BUILD
C25: Particulars | D25: FY2026 | E25: FY2027 | F25: FY2028 | G25: FY2029 | H25: FY2030 | I25: 5-Yr Total | J25: Formula / Notes
C26: EBITDA ($m) | D26: =D22*D10 -> 26674.866 | E26: =E22*D10 -> 27731.191 | F26: =F22*D10 -> 28801.892 | G26: =G22*D10 -> 29869.452 | H26: =H22*D10 -> 30932.296 | I26: =SUM(D26:H26) -> 144009.7 | J26: Revenue x EBITDA Margin
C27: EBIT ($m) | D27: =D22*D11 -> 15585.315 | E27: =E22*D11 -> 16202.494 | F27: =F22*D11 -> 16828.072 | G27: =G22*D11 -> 17451.815 | H27: =H22*D11 -> 18072.802 | I27: =SUM(D27:H27) -> 84140.497 | J27: Revenue x EBIT Margin
C28: NOPAT = EBIT × (1−Tax) | D28: =D27*(1-D12) -> 11221.427 | E28: =E27*(1-D12) -> 11665.795 | F28: =F27*(1-D12) -> 12116.212 | G28: =G27*(1-D12) -> 12565.306 | H28: =H27*(1-D12) -> 13012.417 | I28: =SUM(D28:H28) -> 60581.158 | J28: Net Operating Profit After Tax
C29: Add: D&A ($m) | D29: =D26-D27 -> 11089.551 | E29: =E26-E27 -> 11528.697 | F29: =F26-F27 -> 11973.82 | G29: =G26-G27 -> 12417.637 | H29: =H26-H27 -> 12859.494 | I29: =SUM(D29:H29) -> 59869.2 | J29: EBITDA minus EBIT
C30: Less: CapEx ($m) | D30: =D14*(1+D15)^1 -> 12520.025 | E30: =D14*(1+D15)^2 -> 12707.825 | F30: =D14*(1+D15)^3 -> 12898.443 | G30: =D14*(1+D15)^4 -> 13091.919 | H30: =D14*(1+D15)^5 -> 13288.298 | I30: =SUM(D30:H30) -> 64506.511 | J30: Base CapEx x (1+g)^year
C31: Less: ΔWorking Capital ($m) | D31: =D17+20*(0) -> 300 | E31: =D17+20*(1) -> 320 | F31: =D17+20*(2) -> 340 | G31: =D17+20*(3) -> 360 | H31: =D17+20*(4) -> 380 | I31: =SUM(D31:H31) -> 1700 | J31: Conservative working capital build
C32: FCFF ($m) | D32: =D28+D29-D30-D31 -> 9490.9531 | E32: =E28+E29-E30-E31 -> 10166.668 | F32: =F28+F29-F30-F31 -> 10851.589 | G32: =G28+G29-G30-G31 -> 11531.024 | H32: =H28+H29-H30-H31 -> 12203.613 | I32: =SUM(D32:H32) -> 54243.848 | J32: NOPAT + DA minus CapEx minus DeltaWC
C34: DCF CALCULATION
C35: Particulars | D35: FY2026 | E35: FY2027 | F35: FY2028 | G35: FY2029 | H35: FY2030 | I35: TOTAL | J35: Formula / Notes
C36: Discount Factor 1/(1+WACC)^t | D36: =1/(1+$D$8)^1 -> 0.93023256 | E36: =1/(1+$D$8)^2 -> 0.86533261 | F36: =1/(1+$D$8)^3 -> 0.80496057 | G36: =1/(1+$D$8)^4 -> 0.74880053 | H36: =1/(1+$D$8)^5 -> 0.69655863 | J36: Uses WACC from Key Assumptions cell
C37: PV of FCFF ($m) | D37: =D32*D36 -> 8828.7936 | E37: =E32*E36 -> 8797.5489 | F37: =F32*F36 -> 8735.1017 | G37: =G32*G36 -> 8634.4371 | H37: =H32*H36 -> 8500.532 | I37: =SUM(D37:H37) -> 43496.413 | J37: FCFF x Discount Factor
C39: TERMINAL VALUE (Gordon Growth Model)
C40: Particulars | D40: Value | E40: Basis / Source
C41: Terminal Year FCFF (FY2031) | D41: =H32*(1+$D$9) -> 12508.703 | E41: FY2030 FCFF × (1 + TGR)
C42: Terminal Value TV = FCFF₂₀₃₁ / (WACC−TGR) | D42: =D41/($D$8-$D$9) -> 250174.07 | E42: Gordon Growth Model
C43: PV of Terminal Value | D43: =D42/(1+$D$8)^5 -> 174260.91 | E43: Discounted at WACC over 5 years
C45: ENTERPRISE VALUE & EQUITY BRIDGE
C46: Particulars | D46: Value | E46: Basis / Source
C47: Enterprise Value (EV = PV FCFF + PV TV) | D47: =I37+D43 -> 217757.32 | E47: Sum of PV of FCFFs + PV of Terminal Value
C48: Less: Net Debt (FY2025) | D48: -14362 | E48: Source: Rio Tinto FY2025 Full Year Results (SEC EDGAR 6-K, 19 Feb 2026). Corrected from $14,400m.
C49: Equity Value ($m) | D49: =D47+D48 -> 203395.32 | E49: EV minus net debt
...

Sheet Scenario Manager
C3: RIO TINTO — SCENARIO ANALYSIS (Replicates Excel Scenario Manager Output)
C5: Assumption | D5: Bear Case | E5: Base Case | F5: Bull Case
C6: WACC | D6: 0.0868 | E6: 0.075 | F6: 0.065
C7: Terminal Growth Rate | D7: 0.015 | E7: 0.025 | F7: 0.03
C8: EBITDA Margin | D8: 0.4 | E8: 0.445 | F8: 0.47
C9: Revenue Growth Yr1 | D9: 0.02 | E9: 0.04 | F9: 0.055
C10: Net Debt ($m) | D10: 16000 | E10: 14362 | F10: 13000
C12: SCENARIO OUTPUTS (calculated using DCF assumptions above)
C13: Output Metric | D13: Bear Case | E13: Base Case | F13: Bull Case | G13: Notes
C14: Enterprise Value (USD $bn) | D14: 92.7 | E14: 219.5 | F14: 401.4 | G14: PV of FCFFs + PV Terminal Value
C15: Equity Value per Share (AUD) | D15: 73.24 | E15: 195.96 | F15: 370.98 | G15: After net debt deduction and FX conversion
C16: vs Market Price (A$179.79) | D16: -0.5926 | E16: 0.0899 | F16: 1.0634 | G16: (Intrinsic − Market) / Market
C17: Recommendation | D17: SELL | E17: BUY | F17: BUY | G17: BUY >+8%, SELL <-8%, HOLD otherwise
C18: Implied P/E (x) | D18: 19.2 | E18: 20.6 | F18: 35.4 | G18: Market cap implied / normalised earnings
C19: Implied EV/EBITDA (x) | D19: 4 | E19: 8.6 | F19: 14.8 | G19: Implied EV / FY2025 normalised EBITDA
C21: QUALITATIVE SCENARIO DRIVERS
C22: Driver | D22: Bear Case | E22: Base Case | F22: Bull Case
C23: Iron ore price | D23: ↓ -15%, property slump | E23: Stable ~$95/t CFR | F23: ↑ +10%, India demand
C24: Copper production | D24: Oyu Tolgoi delays | E24: On-track ramp-up | F24: Ahead of schedule
C25: CapEx delivery | D25: 10% cost overrun | E25: On budget | F25: Under budget
C26: China demand | D26: Structural decline | E26: Moderate growth | F26: Infrastructure stimulus
C27: AUD/USD | D27: ↑ to 0.70 (cost ↑) | E27: Stable ~0.645 | F27: ↓ to 0.60 (cost ↓)
C28: Simandou ramp | D28: Delayed by 2+ years | E28: On schedule | F28: Early production 2026

Sheet Scenario Summary
C4: Scenario Summary
C6: Particulars | E6: Current Values | F6: Bear Case | G6: Base Case | H6: Bull Case
F7: Created by janvi malhotra on 4/06/2026 | G7: Created by janvi malhotra on 4/06/2026 | H7: Created by janvi malhotra on 4/06/2026
C8: Changing Cells:
C9: WACC | E9: 0.075 | F9: 0.0868 | G9: 0.075 | H9: 0.065
C10: Terminal Growth Rate | E10: 0.025 | F10: 0.015 | G10: 0.025 | H10: 0.03
C11: EBITDA Margin | E11: 0.445 | F11: 0.4 | G11: 0.445 | H11: 0.47
C12: Revenue Growth | E12: 0.04 | F12: 0.02 | G12: 0.04 | H12: 0.055
C13: Result Cells:
C14: Enterprise Value | E14: 217757.32 | F14: 92191.54 | G14: 217757.32 | H14: 397386.35
C15: AUD Share Price | E15: 194.29549 | F15: 74.347476 | G15: 194.29549 | H15: 365.88798
C16: Upside/(Downside) | E16: 0.080680185 | F16: -0.58647602 | G16: 0.080680185 | H16: 1.0350853
C17: Recommendation | E17: BUY | F17: SELL | G17: BUY | H17: BUY
C18: Notes: Current Values column represents values of changing cells at time Scenario Summary Report was created. Changing cells for each scenario are highlighted in gray.

Sheet Goal Seek Analysis
C3: RIO TINTO — GOAL SEEK ANALYSIS
C5: GOAL SEEK QUESTIONS
C6: Goal Seek Question | D6: Set Cell | E6: Value | F6: By Changing Cell
C7: What WACC makes intrinsic value = market price? | D7: DCF Model: AUD share price | E7: 179.79 (market) | F7: DCF Model: WACC cell (B6)
C8: What TGR makes intrinsic value = market price? | D8: DCF Model: AUD share price | E8: 179.79 (market) | F8: DCF Model: TGR cell (B7)
C9: What revenue growth breaks the bull case? | D9: DCF Model: AUD share price | E9: 200.00 (bull) | F9: DCF Model: Revenue Yr1 Growth
C10: What EBITDA margin justifies current price? | D10: DCF Model: AUD share price | E10: 179.79 (market) | F10: DCF Model: EBITDA Margin
C11: What net debt level tips to SELL signal? | D11: DCF Model: Recommendation | E11: SELL | F11: DCF Model: Net Debt cell
C13: BREAK-EVEN ANALYSIS (Pre-computed)
C14: Metric | D14: Break-Even Value | E14: Current Value | F14: Notes
C15: Break-even WACC (price = A$179.79) | D15: 7.91% | E15: 7.50% (base) | F15: WACC above this → SELL signal
C16: Break-even TGR (price = A$179.79) | D16: 1.99% | E16: 2.50% (base) | F16: TGR below this → SELL signal
C17: Break-even iron ore price (approx) | D17: ~$88/t CFR | E17: ~$95/t CFR | F17: Approx. based on FY2025 sensitivity
C18: Minimum EBITDA margin for HOLD | D18: ~42.0% | E18: 44.5% (base) | F18: Margin below this → SELL signal at base WACC
